{"uuid": "991eabc6-d52f-45c0-9a0a-c9174fb80975", "children": ["9a4f5862-0822-424d-b83e-f7f0683631f9", "0fbaa7a5-d540-4b3d-8cad-92d972791845", "0cd7b874-b1a2-4094-a107-3b4221e05e4d", "f721911f-1b52-452d-a7e3-8a51be9cc779", "af54fb77-92f5-47ea-9c51-589bec81da35", "a2b9b1bf-ef33-4cc8-84ee-81049e3467c4", "084804df-e571-42b3-99f1-6c76fb8499fd", "5b704a2f-e4c7-44c7-8b52-9fe3d02af87a", "66d63458-f050-4f25-8d8c-7bcd3692d996", "80b2d5af-6070-494e-8bfc-486af407c02b", "751a4b79-a54a-46ab-9cf0-bf508375bafa", "ad25197b-a9a8-4c7e-9e31-1c8b9041b8b4", "42db18e8-19ca-4906-9d4b-d9c093617ba2", "177e9b96-d493-45af-9194-c1cc4e2aafa0", "42033d96-733e-4ed9-8bc0-d7e28a6d4257", "5dc57ea6-1226-4182-a6a0-2ca597e4d30d"], "befores": [{"name": "xunit_setup_class_fixture_TestCases", "status": "broken", "statusDetails": {"message": "requests.exceptions.SSLError: HTTPSConnectionPool(host='api.test.xiangcaohuyu.com', port=443): Max retries exceeded with url: /v1/app/basic/getDeviceToken (Caused by SSLError(SSLCertVerificationError(1, '[SSL: CERTIFICATE_VERIFY_FAILED] certificate verify failed: unable to get local issuer certificate (_ssl.c:1056)')))\n", "trace": "  File \"C:\\Users\\Administrator\\AppData\\Local\\Programs\\Python\\Python37\\lib\\site-packages\\pluggy\\callers.py\", line 187, in _multicall\n    res = hook_impl.function(*args)\n  File \"C:\\Users\\Administrator\\AppData\\Local\\Programs\\Python\\Python37\\lib\\site-packages\\_pytest\\fixtures.py\", line 1126, in pytest_fixture_setup\n    result = call_fixture_func(fixturefunc, request, kwargs)\n  File \"C:\\Users\\Administrator\\AppData\\Local\\Programs\\Python\\Python37\\lib\\site-packages\\_pytest\\fixtures.py\", line 925, in call_fixture_func\n    fixture_result = next(generator)\n  File \"C:\\Users\\Administrator\\AppData\\Local\\Programs\\Python\\Python37\\lib\\site-packages\\_pytest\\python.py\", line 811, in xunit_setup_class_fixture\n    _call_with_optional_argument(func, self.obj)\n  File \"C:\\Users\\Administrator\\AppData\\Local\\Programs\\Python\\Python37\\lib\\site-packages\\_pytest\\python.py\", line 739, in _call_with_optional_argument\n    func(arg)\n  File \"D:\\ybAPI\\cases\\test_03_message.py\", line 20, in setup_class\n    cls.public_params=get_params.public_params()\n  File \"C:\\pyapp\\app\\ybAPI\\utils\\public_params.py\", line 16, in public_params\n    res_temp=self.get_userinfo()\n  File \"C:\\pyapp\\app\\ybAPI\\utils\\public_params.py\", line 10, in get_userinfo\n    access_token=get_token.get_user_token('13999990007','123456')\n  File \"C:\\pyapp\\app\\ybAPI\\utils\\get_token.py\", line 22, in get_user_token\n    devices_token=self.get_devices_token()\n  File \"C:\\pyapp\\app\\ybAPI\\utils\\get_token.py\", line 17, in get_devices_token\n    devices_token=requests.post(url,files=public_params)\n  File \"C:\\Users\\Administrator\\AppData\\Local\\Programs\\Python\\Python37\\lib\\site-packages\\requests\\api.py\", line 116, in post\n    return request('post', url, data=data, json=json, **kwargs)\n  File \"C:\\Users\\Administrator\\AppData\\Local\\Programs\\Python\\Python37\\lib\\site-packages\\requests\\api.py\", line 60, in request\n    return session.request(method=method, url=url, **kwargs)\n  File \"C:\\Users\\Administrator\\AppData\\Local\\Programs\\Python\\Python37\\lib\\site-packages\\requests\\sessions.py\", line 524, in request\n    resp = self.send(prep, **send_kwargs)\n  File \"C:\\Users\\Administrator\\AppData\\Local\\Programs\\Python\\Python37\\lib\\site-packages\\requests\\sessions.py\", line 637, in send\n    r = adapter.send(request, **kwargs)\n  File \"C:\\Users\\Administrator\\AppData\\Local\\Programs\\Python\\Python37\\lib\\site-packages\\requests\\adapters.py\", line 514, in send\n    raise SSLError(e, request=request)\n"}, "start": 1634899948613, "stop": 1634899948700}], "start": 1634899948613, "stop": 1634899950479}